Traceback (most recent call last):
  File "C:\Users\akhyar\AppData\Roaming\Python\Python311\site-packages\jupyter_cache\executors\utils.py", line 58, in single_nb_execution
    executenb(
  File "C:\Program Files\Python311\Lib\site-packages\nbclient\client.py", line 1314, in execute
    return NotebookClient(nb=nb, resources=resources, km=km, **kwargs).execute()
           ^^^^^^^^^^^^^^^^^^^^^^^^^^^^^^^^^^^^^^^^^^^^^^^^^^^^^^^^^^^^^^^^^^^^^
  File "C:\Program Files\Python311\Lib\site-packages\jupyter_core\utils\__init__.py", line 165, in wrapped
    return loop.run_until_complete(inner)
           ^^^^^^^^^^^^^^^^^^^^^^^^^^^^^^
  File "C:\Program Files\Python311\Lib\asyncio\base_events.py", line 654, in run_until_complete
    return future.result()
           ^^^^^^^^^^^^^^^
  File "C:\Program Files\Python311\Lib\site-packages\nbclient\client.py", line 709, in async_execute
    await self.async_execute_cell(
  File "C:\Program Files\Python311\Lib\site-packages\nbclient\client.py", line 1062, in async_execute_cell
    await self._check_raise_for_error(cell, cell_index, exec_reply)
  File "C:\Program Files\Python311\Lib\site-packages\nbclient\client.py", line 918, in _check_raise_for_error
    raise CellExecutionError.from_cell_and_msg(cell, exec_reply_content)
nbclient.exceptions.CellExecutionError: An error occurred while executing the following cell:
------------------
judul = []
tanggal = []
isi = []
url_list = []
kategori_list = []

base_urls = [
    "https://www.cnbcindonesia.com/research/indeks/127/",
    "https://www.cnbcindonesia.com/news/indeks/3/",
    "https://www.cnbcindonesia.com/tech/indeks/12/",
    "https://www.cnbcindonesia.com/market/indeks/5/"
]
categories = [
    "Research",
    "News",
    "Tech",q
    "Market"
]
------------------


[1;36m  Cell [1;32mIn[2], line 17[1;36m[0m
[1;33m    "Market"[0m
[1;37m    ^[0m
[1;31mSyntaxError[0m[1;31m:[0m invalid syntax


